>>> Author.objects.create(name='Alex')
Traceback (most recent call last):
  File "<console>", line 1, in <module>
  File "/home/user/Yandex.Disk/py_skill/NewsPortal/venv/lib/python3.8/site-packages/django/db/models/manager.py", line 85, in manager_method
    return getattr(self.get_queryset(), name)(*args, **kwargs)
  File "/home/user/Yandex.Disk/py_skill/NewsPortal/venv/lib/python3.8/site-packages/django/db/models/query.py", line 455, in create
    obj = self.model(**kwargs)
  File "/home/user/Yandex.Disk/py_skill/NewsPortal/venv/lib/python3.8/site-packages/django/db/models/base.py", line 507, in __init__
    raise TypeError("%s() got an unexpected keyword argument '%s'" % (cls.__name__, kwarg))
TypeError: Author() got an unexpected keyword argument 'name'
>>> Author.objects.create(user='Alex')
Traceback (most recent call last):
  File "<console>", line 1, in <module>
  File "/home/user/Yandex.Disk/py_skill/NewsPortal/venv/lib/python3.8/site-packages/django/db/models/manager.py", line 85, in manager_method
    return getattr(self.get_queryset(), name)(*args, **kwargs)
  File "/home/user/Yandex.Disk/py_skill/NewsPortal/venv/lib/python3.8/site-packages/django/db/models/query.py", line 455, in create
    obj = self.model(**kwargs)
  File "/home/user/Yandex.Disk/py_skill/NewsPortal/venv/lib/python3.8/site-packages/django/db/models/base.py", line 489, in __init__
    _setattr(self, field.name, rel_obj)
  File "/home/user/Yandex.Disk/py_skill/NewsPortal/venv/lib/python3.8/site-packages/django/db/models/fields/related_descriptors.py", line 310, in __set__
    super().__set__(instance, value)
  File "/home/user/Yandex.Disk/py_skill/NewsPortal/venv/lib/python3.8/site-packages/django/db/models/fields/related_descriptors.py", line 215, in __set__
    raise ValueError(
ValueError: Cannot assign "'Alex'": "Author.user" must be a "User" instance.
>>> Author.objects.create(user=Alex)
Traceback (most recent call last):
  File "<console>", line 1, in <module>
NameError: name 'Alex' is not defined
>>> Category.objects.a
Category.objects.aggregate(    Category.objects.alias(        Category.objects.all(          Category.objects.annotate(     Category.objects.auto_created
>>> Category.objects.creat
Category.objects.create(           Category.objects.creation_counter
>>> Category.objects.create(category_name=tech)
Traceback (most recent call last):
  File "<console>", line 1, in <module>
NameError: name 'tech' is not defined
>>> Category.objects.create(category_name = 'Tech')
<Category: Category object (1)>
>>> Category.objects.create(category_name = 'Avto')
<Category: Category object (2)>
>>> Category.objects.create(category_name = 'Medicine')
<Category: Category object (3)>
>>> Category.objects.create(category_name = 'Other')
<Category: Category object (4)>
>>> Post.objects.create(news_text = 'some text', p_chose = Post.article)
Traceback (most recent call last):
  File "/home/user/Yandex.Disk/py_skill/NewsPortal/venv/lib/python3.8/site-packages/django/db/backends/utils.py", line 85, in _execute
    return self.cursor.execute(sql, params)
  File "/home/user/Yandex.Disk/py_skill/NewsPortal/venv/lib/python3.8/site-packages/django/db/backends/sqlite3/base.py", line 416, in execute
    return Database.Cursor.execute(self, query, params)
sqlite3.IntegrityError: NOT NULL constraint failed: News_post.author_id

The above exception was the direct cause of the following exception:

Traceback (most recent call last):
  File "<console>", line 1, in <module>
  File "/home/user/Yandex.Disk/py_skill/NewsPortal/venv/lib/python3.8/site-packages/django/db/models/manager.py", line 85, in manager_method
    return getattr(self.get_queryset(), name)(*args, **kwargs)
  File "/home/user/Yandex.Disk/py_skill/NewsPortal/venv/lib/python3.8/site-packages/django/db/models/query.py", line 457, in create
    obj.save(force_insert=True, using=self.db)
  File "/home/user/Yandex.Disk/py_skill/NewsPortal/venv/lib/python3.8/site-packages/django/db/models/base.py", line 743, in save
    self.save_base(using=using, force_insert=force_insert,
  File "/home/user/Yandex.Disk/py_skill/NewsPortal/venv/lib/python3.8/site-packages/django/db/models/base.py", line 780, in save_base
    updated = self._save_table(
  File "/home/user/Yandex.Disk/py_skill/NewsPortal/venv/lib/python3.8/site-packages/django/db/models/base.py", line 885, in _save_table
    results = self._do_insert(cls._base_manager, using, fields, returning_fields, raw)
  File "/home/user/Yandex.Disk/py_skill/NewsPortal/venv/lib/python3.8/site-packages/django/db/models/base.py", line 923, in _do_insert
    return manager._insert(
  File "/home/user/Yandex.Disk/py_skill/NewsPortal/venv/lib/python3.8/site-packages/django/db/models/manager.py", line 85, in manager_method
    return getattr(self.get_queryset(), name)(*args, **kwargs)
  File "/home/user/Yandex.Disk/py_skill/NewsPortal/venv/lib/python3.8/site-packages/django/db/models/query.py", line 1301, in _insert
    return query.get_compiler(using=using).execute_sql(returning_fields)
  File "/home/user/Yandex.Disk/py_skill/NewsPortal/venv/lib/python3.8/site-packages/django/db/models/sql/compiler.py", line 1441, in execute_sql
    cursor.execute(sql, params)
  File "/home/user/Yandex.Disk/py_skill/NewsPortal/venv/lib/python3.8/site-packages/django/db/backends/utils.py", line 99, in execute
    return super().execute(sql, params)
  File "/home/user/Yandex.Disk/py_skill/NewsPortal/venv/lib/python3.8/site-packages/django/db/backends/utils.py", line 67, in execute
    return self._execute_with_wrappers(sql, params, many=False, executor=self._execute)
  File "/home/user/Yandex.Disk/py_skill/NewsPortal/venv/lib/python3.8/site-packages/django/db/backends/utils.py", line 76, in _execute_with_wrappers
    return executor(sql, params, many, context)
  File "/home/user/Yandex.Disk/py_skill/NewsPortal/venv/lib/python3.8/site-packages/django/db/backends/utils.py", line 85, in _execute
    return self.cursor.execute(sql, params)
  File "/home/user/Yandex.Disk/py_skill/NewsPortal/venv/lib/python3.8/site-packages/django/db/utils.py", line 90, in __exit__
    raise dj_exc_value.with_traceback(traceback) from exc_value
  File "/home/user/Yandex.Disk/py_skill/NewsPortal/venv/lib/python3.8/site-packages/django/db/backends/utils.py", line 85, in _execute
    return self.cursor.execute(sql, params)
  File "/home/user/Yandex.Disk/py_skill/NewsPortal/venv/lib/python3.8/site-packages/django/db/backends/sqlite3/base.py", line 416, in execute
    return Database.Cursor.execute(self, query, params)
django.db.utils.IntegrityError: NOT NULL constraint failed: News_post.author_id
>>> Post.objects.create(news_text = 'some text', p_chose = Post.article, author = 'Alex')
Traceback (most recent call last):
  File "<console>", line 1, in <module>
  File "/home/user/Yandex.Disk/py_skill/NewsPortal/venv/lib/python3.8/site-packages/django/db/models/manager.py", line 85, in manager_method
    return getattr(self.get_queryset(), name)(*args, **kwargs)
  File "/home/user/Yandex.Disk/py_skill/NewsPortal/venv/lib/python3.8/site-packages/django/db/models/query.py", line 455, in create
    obj = self.model(**kwargs)
  File "/home/user/Yandex.Disk/py_skill/NewsPortal/venv/lib/python3.8/site-packages/django/db/models/base.py", line 489, in __init__
    _setattr(self, field.name, rel_obj)
  File "/home/user/Yandex.Disk/py_skill/NewsPortal/venv/lib/python3.8/site-packages/django/db/models/fields/related_descriptors.py", line 215, in __set__
    raise ValueError(
ValueError: Cannot assign "'Alex'": "Post.author" must be a "Author" instance.
>>> Post.objects.create(news_text = 'some text')
Traceback (most recent call last):
  File "/home/user/Yandex.Disk/py_skill/NewsPortal/venv/lib/python3.8/site-packages/django/db/backends/utils.py", line 85, in _execute
    return self.cursor.execute(sql, params)
  File "/home/user/Yandex.Disk/py_skill/NewsPortal/venv/lib/python3.8/site-packages/django/db/backends/sqlite3/base.py", line 416, in execute
    return Database.Cursor.execute(self, query, params)
sqlite3.IntegrityError: NOT NULL constraint failed: News_post.author_id

The above exception was the direct cause of the following exception:

Traceback (most recent call last):
  File "<console>", line 1, in <module>
  File "/home/user/Yandex.Disk/py_skill/NewsPortal/venv/lib/python3.8/site-packages/django/db/models/manager.py", line 85, in manager_method
    return getattr(self.get_queryset(), name)(*args, **kwargs)
  File "/home/user/Yandex.Disk/py_skill/NewsPortal/venv/lib/python3.8/site-packages/django/db/models/query.py", line 457, in create
    obj.save(force_insert=True, using=self.db)
  File "/home/user/Yandex.Disk/py_skill/NewsPortal/venv/lib/python3.8/site-packages/django/db/models/base.py", line 743, in save
    self.save_base(using=using, force_insert=force_insert,
  File "/home/user/Yandex.Disk/py_skill/NewsPortal/venv/lib/python3.8/site-packages/django/db/models/base.py", line 780, in save_base
    updated = self._save_table(
  File "/home/user/Yandex.Disk/py_skill/NewsPortal/venv/lib/python3.8/site-packages/django/db/models/base.py", line 885, in _save_table
    results = self._do_insert(cls._base_manager, using, fields, returning_fields, raw)
  File "/home/user/Yandex.Disk/py_skill/NewsPortal/venv/lib/python3.8/site-packages/django/db/models/base.py", line 923, in _do_insert
    return manager._insert(
  File "/home/user/Yandex.Disk/py_skill/NewsPortal/venv/lib/python3.8/site-packages/django/db/models/manager.py", line 85, in manager_method
    return getattr(self.get_queryset(), name)(*args, **kwargs)
  File "/home/user/Yandex.Disk/py_skill/NewsPortal/venv/lib/python3.8/site-packages/django/db/models/query.py", line 1301, in _insert
    return query.get_compiler(using=using).execute_sql(returning_fields)
  File "/home/user/Yandex.Disk/py_skill/NewsPortal/venv/lib/python3.8/site-packages/django/db/models/sql/compiler.py", line 1441, in execute_sql
    cursor.execute(sql, params)
  File "/home/user/Yandex.Disk/py_skill/NewsPortal/venv/lib/python3.8/site-packages/django/db/backends/utils.py", line 99, in execute
    return super().execute(sql, params)
  File "/home/user/Yandex.Disk/py_skill/NewsPortal/venv/lib/python3.8/site-packages/django/db/backends/utils.py", line 67, in execute
    return self._execute_with_wrappers(sql, params, many=False, executor=self._execute)
  File "/home/user/Yandex.Disk/py_skill/NewsPortal/venv/lib/python3.8/site-packages/django/db/backends/utils.py", line 76, in _execute_with_wrappers
    return executor(sql, params, many, context)
  File "/home/user/Yandex.Disk/py_skill/NewsPortal/venv/lib/python3.8/site-packages/django/db/backends/utils.py", line 85, in _execute
    return self.cursor.execute(sql, params)
  File "/home/user/Yandex.Disk/py_skill/NewsPortal/venv/lib/python3.8/site-packages/django/db/utils.py", line 90, in __exit__
    raise dj_exc_value.with_traceback(traceback) from exc_value
  File "/home/user/Yandex.Disk/py_skill/NewsPortal/venv/lib/python3.8/site-packages/django/db/backends/utils.py", line 85, in _execute
    return self.cursor.execute(sql, params)
  File "/home/user/Yandex.Disk/py_skill/NewsPortal/venv/lib/python3.8/site-packages/django/db/backends/sqlite3/base.py", line 416, in execute
    return Database.Cursor.execute(self, query, params)
django.db.utils.IntegrityError: NOT NULL constraint failed: News_post.author_id
>>> Author.objects.create(user=Alex)
Traceback (most recent call last):
  File "<console>", line 1, in <module>
NameError: name 'Alex' is not defined
>>> Author.objects.create(user = Author.Alex)
Traceback (most recent call last):
  File "<console>", line 1, in <module>
AttributeError: type object 'Author' has no attribute 'Alex'
>>>
